Workbook

Sheet 初期入力
A1: 廃棄する機器所有者等 | D1: 廃棄する機器の種類及び台数
A2: 回付年月日 | D2: エアコンディショナー
A3: 承諾年月日 | D3: 冷蔵・冷凍機器
A4: 所有者の名称
A5: 所有者の住所 | D5: 回収
A6: 建物の名称
A7: 建物の住所
A8: 略称
A9: 担当者
A10: 部署名
A11: 電話
A12: FAX
A14: 取次者 ( 1 ) | D14: 回収内容 | E14: R11.12.502 | G14: R22.123 | I14: R407C.410A.32.134a
A15: 回付年月日 | E15: CFC | G15: HCFC | I15: HFC | K15: 計
A16: 名称 | D16: エアコンディショナー
A17: 住所 | D17: 冷蔵機器及び冷凍機器
A18: 担当者 | D18: 計
A19: 部署名 | D19: 銘板記載充填量
A20: 電話 | D20: 回収不能台数 | E20: 0
A21: FAX
A23: 取次者 ( 2 )
A24: 回付年月日
A25: 名称
A26: 住所
A27: 担当者
A28: 部署名
A29: 電話
A30: FAX
A32: 充填回収業者
A33: 登録番号 | B33: 0110100851
A34: 登録都道府県 | B34: 北海道
A35: 名称 | B35: テクノエンジニアリング㈱
A36: 住所 | B36: 〒003-0011 札幌市白石区中央1条5丁目6-20
A37: 担当者 | B37: 中野 勝之
A38: 部署名 | B38: 工事部
A39: 回収技術者 | B39: 中野 勝之
A40: 引取り年月日
A41: 証明書発行日
A42: 電話 | B42: 011-827-6330
A43: FAX | B43: 011-827-6331

Sheet A票
A1: Ａ 票 | C1: 委託確認書 | S1: 機器の所有者等が保存
A3: 汎用版 (主に再委託用)
A5: 機器整備・修理 | D5: (機器の整備・修理時に使用する場合は、左記にレ点を記入) | O5: 伝票番号
A6: 廃棄する機器 の所有者等 | C6: 機器所有者等の氏名又は名称 | G6: =IF(初期入力!$B$4="","",初期入力!$B$4) | O6: 交付の年月日 | R6: =IF(初期入力!$B$2="","",初期入力!$B$2)
C7: 上記の住所 | G7: =IF(初期入力!$B$5="","",初期入力!$B$5) | O7: 電 話 | R7: =IF(初期入力!$B$11="","",初期入力!$B$11)
A8: (第1種特定製品 廃棄等実施者) | C8: 担当者 | G8: 部署名 | H8: =IF(初期入力!$B$10="","",初期入力!$B$10) | K8: 氏名 | M8: =IF(初期入力!$B$9="","",初期入力!$B$9) | O8: F A X | R8: =IF(初期入力!$B$12="","",初期入力!$B$12)
C9: 廃棄する機器がある施設(建物)名 | G9: =IF(初期入力!$B$6="","",初期入力!$B$6)
A10: 整備の場合 : 整備する機器の 所有者等 (第1種特定製品 の整備の発注者) | C10: 上記の住所 | G10: =IF(初期入力!$B$7="","",初期入力!$B$7)
C11: 廃棄する機器の種類及び台数 | N11: 建物解体(含修繕・模様替え)の有無(下記該当に〇印)
C12: エアコンディショナー | G12: =IF(初期入力!$E$2="","",初期入力!$E$2) | H12: 冷蔵及び冷凍機器 | L12: =IF(初期入力!$E$3="","",初期入力!$E$3) | N12: 解体(修繕等)あり | S12: 解体(修繕等)なし
C13: フロン類の引渡し先 (右記該当枠にレ点) | H13: 第1種フロン類充填回収業者に直接依頼する (第1種フロン類充填回収業者欄に記入する) | P13: 取次者(1)に委託する (取次者(1)欄に記入する)
A15: 取次者(1) (第1種フロン類 引渡受託者) | C15: 取次者(1)の氏名又は名称 | G15: =IF(初期入力!$B$16="","",初期入力!$B$16) | O15: 回付の年月日
C16: 上記の住所 | G16: =IF(初期入力!$B$17="","",初期入力!$B$17) | O16: 電 話 | R16: =IF(初期入力!$B$20="","",初期入力!$B$20)
C17: 担当者 | G17: 部署名 | K17: 氏名 | O17: F A X | R17: =IF(初期入力!$B$21="","",初期入力!$B$21)
A18: 整備の場合 : (第1種特定 製品の整備者) | C18: 下記の者にフロン類を引渡します。(引渡し先にレ点を記入)
C19: 取次者(2) | H19: 取次者(2)に再委託することを承諾します。 | O19: 承諾の年月日
C20: 第1種フロン類充填回収業者 | H20: 廃棄する機器所有者等 | O20: 担当者
H21: の氏名又は名称
A23: 取次者(2) (第1種フロン類 引渡受託者) | C23: 取次者(2)の氏名又は名称 | O23: 回付の年月日
C24: 上記の住所 | G24: 〒 | O24: 電 話
C25: 担当者 | G25: 部署名 | K25: 氏名 | O25: F A X
C26: 下記の者にフロン類を引渡します。(引渡し先にレ点を記入)
C27: 取次者(3)→(別紙『補足用』を使用して下さい。) | L27: 第1種フロン類充填回収業者
A29: 第1種 フロン類 充填回収業者 | C29: 登録番号 | G29: 0110100280 | J29: フロン類引取り終了した年月日 | P29: 引取証明書 交付の年月日
C30: 登録都道府県 | G30: 北海道
C31: 第1種フロン類充填回収業者 | G31: テクノエンジニアリング株式会社 | O31: 冷媒回収
C32: の氏名又は名称 | O32: 技術者氏名
C33: 上記の住所 | G33: 〒003-0011札幌市白石区中央１条５丁目6-20 | O33: 電 話 | R33: 011-827-6330
C34: 担当者 | G34: 部署名 | K34: 氏名 | O34: F A X | R34: 011-827-6331
A36: 廃棄する機器の所有者等 (以下、機器の所有者等) の注意事項
A37: ①A票の機器の所有者等欄と取次者 (1) 欄に必要事項を記入し、A票を保存 (3年間) し、B票以下を取次者 (1) に交付します。
A38: ②廃棄する機器の種類欄には、エアコンディショナーと冷凍・冷蔵機器を区分けして記載必要があります。エアコンディショナーとは人を
A39: 冷暖房する機器、冷凍・冷蔵機器とは物を冷凍・冷蔵する機器のことです。一般的な目安として、表紙裏の表を参照して下さい。
A40: ③この書類を交付後、30日 (建物の全部または一部解体を伴う場合は90日) を経過してもE票または、E票 (写) が回付されない場合は、回収
A41: 場所の都道府県知事へ報告する必要があります。
A42: ④この行程管理票は、複写式であるため、できるだけ強く記入して下さい。
A44: (
A45: 引
A46: 渡
A47: し
...

Sheet B票
A1: B 票 | C1: 再委託承諾書 | S1: 機器の所有者等が保存
A3: 汎用版 (主に再委託用)
A5: 機器整備・修理 | D5: (機器の整備・修理時に使用する場合は、左記にレ点を記入) | O5: 伝票番号
A6: 廃棄する機器 の所有者等 | C6: 機器所有者等の氏名又は名称 | G6: =IF(初期入力!$B$4="","",初期入力!$B$4) | O6: 交付の年月日 | R6: =IF(初期入力!$B$2="","",初期入力!$B$2)
C7: 上記の住所 | G7: =IF(初期入力!$B$5="","",初期入力!$B$5) | O7: 電 話 | R7: =IF(初期入力!$B$11="","",初期入力!$B$11)
A8: (第1種特定製品 廃棄等実施者) | C8: 担当者 | G8: 部署名 | H8: =IF(初期入力!$B$10="","",初期入力!$B$10) | K8: 氏名 | M8: =IF(初期入力!$B$9="","",初期入力!$B$9) | O8: F A X | R8: =IF(初期入力!$B$12="","",初期入力!$B$12)
C9: 廃棄する機器がある施設(建物)名 | G9: =IF(初期入力!$B$6="","",初期入力!$B$6)
A10: 整備の場合 : 整備する機器の 所有者等 (第1種特定製品 の整備の発注者) | C10: 上記の住所 | G10: =IF(初期入力!$B$7="","",初期入力!$B$7)
C11: 廃棄する機器の種類及び台数 | N11: 建物解体(含修繕・模様替え)の有無(下記該当に〇印)
C12: エアコンディショナー | G12: =IF(初期入力!$E$2="","",初期入力!$E$2) | H12: 冷蔵及び冷凍機器 | L12: =IF(初期入力!$E$3="","",初期入力!$E$3) | N12: 解体(修繕等)あり | S12: 解体(修繕等)なし
C13: フロン類の引渡し先 (右記該当枠にレ点) | H13: 第1種フロン類充填回収業者に直接依頼する (第1種フロン類充填回収業者欄に記入する) | P13: 取次者(1)に委託する (取次者(1)欄に記入する)
A15: 取次者(1) (第1種フロン類 引渡受託者) | C15: 取次者(1)の氏名又は名称 | G15: =IF(初期入力!$B$16="","",初期入力!$B$16) | O15: 回付の年月日
C16: 上記の住所 | G16: =IF(初期入力!$B$17="","",初期入力!$B$17) | O16: 電 話 | R16: =IF(初期入力!$B$20="","",初期入力!$B$20)
C17: 担当者 | G17: 部署名 | H17: =IF(初期入力!$B$19="","",初期入力!$B$19) | K17: 氏名 | M17: =IF(初期入力!$B$18="","",初期入力!$B$18) | O17: F A X | R17: =IF(初期入力!$B$21="","",初期入力!$B$21)
A18: 整備の場合 : (第1種特定 製品の整備者) | C18: 下記の者にフロン類を引渡します。(引渡し先にレ点を記入)
C19: 取次者(2) | H19: 取次者(2)に再委託することを承諾します。 | O19: 承諾の年月日
C20: 第1種フロン類充填回収業者 | H20: 廃棄する機器所有者等 | L20: =IF(初期入力!$B$8="","",初期入力!$B$8) | O20: 担当者
H21: の氏名又は名称
A23: 取次者(2) (第1種フロン類 引渡受託者) | C23: 取次者(2)の氏名又は名称 | G23: =IF(初期入力!$B$25="","",初期入力!$B$25) | O23: 回付の年月日
C24: 上記の住所 | G24: =IF(初期入力!$B$26="","",初期入力!$B$26) | O24: 電 話 | R24: =IF(初期入力!$B$29="","",初期入力!$B$29)
C25: 担当者 | G25: 部署名 | H25: =IF(初期入力!$B$28="","",初期入力!$B$28) | K25: 氏名 | M25: =IF(初期入力!$B$27="","",初期入力!$B$27) | O25: F A X | R25: =IF(初期入力!$B$30="","",初期入力!$B$30)
C26: 下記の者にフロン類を引渡します。(引渡し先にレ点を記入)
C27: 取次者(3)→(別紙『補足用』を使用して下さい。) | L27: 第1種フロン類充填回収業者
A29: 第1種 フロン類 充填回収業者 | C29: 登録番号 | J29: フロン類引取り終了した年月日 | P29: 引取証明書 交付の年月日
C30: 登録都道府県
C31: 第1種フロン類充填回収業者 | O31: 冷媒回収
C32: の氏名又は名称 | O32: 技術者氏名
C33: 上記の住所 | G33: 〒 | O33: 電 話
C34: 担当者 | G34: 部署名 | K34: 氏名 | O34: F A X
A36: 取次者 ( 1 ) の注意事項 | N36: 機器の所有者等の注意事項
A37: ①B票は、フロン類の回収をさらに取次者 ( 2 ) に委託 (再委託) する場合に使用します。 | N37: 取次者(1)より、B票以下を提示のうえ、フロン
A38: この場合、取次者 ( 2 ) 欄に記入し、廃棄する機器所有者等 (以下、機器の所有者 | N38: 類の回収を取次者(2)に再委託の諾否を求めら
A39: 等) に再委託の承諾を得なければなりません。機器の所有者等の承諾の諾否は取次者 | N39: れ、承諾する場合は、B票の取次者(1)欄下部(太
A40: ( 1 ) 欄下部 (太線内) にもらってください。 | N40: 線内)に承諾する旨を記載し、B票を保存(3年間)
A41: ②B票に機器の所有者等の諾否をもらい、B票は機器の所有者等に渡します。C票以下 | N41: するとともに、C票以下を取次者(1)に交付
A42: を持ち帰りC票に記入のうえC票を保存(3年間)し、D票以下を取次者(2)に回付します。 | N42: してください。
A44: (
A45: 引
A46: 渡
A47: し
...

Sheet C票
A1: C 票 | C1: 委託確認書 兼 再委託承諾書 (写) | S1: 取次者 ( 1 ) が保存
A3: 汎用版 (主に再委託用)
A5: 機器整備・修理 | D5: (機器の整備・修理時に使用する場合は、左記にレ点を記入) | O5: 伝票番号
A6: 廃棄する機器 の所有者等 | C6: 機器所有者等の氏名又は名称 | G6: =IF(初期入力!$B$4="","",初期入力!$B$4) | O6: 交付の年月日 | R6: =IF(初期入力!$B$2="","",初期入力!$B$2)
C7: 上記の住所 | G7: =IF(初期入力!$B$5="","",初期入力!$B$5) | O7: 電 話 | R7: =IF(初期入力!$B$11="","",初期入力!$B$11)
A8: (第1種特定製品 廃棄等実施者) | C8: 担当者 | G8: 部署名 | H8: =IF(初期入力!$B$10="","",初期入力!$B$10) | K8: 氏名 | M8: =IF(初期入力!$B$9="","",初期入力!$B$9) | O8: F A X | R8: =IF(初期入力!$B$12="","",初期入力!$B$12)
C9: 廃棄する機器がある施設(建物)名 | G9: =IF(初期入力!$B$6="","",初期入力!$B$6)
A10: 整備の場合 : 整備する機器の 所有者等 (第1種特定製品 の整備の発注者) | C10: 上記の住所 | G10: =IF(初期入力!$B$7="","",初期入力!$B$7)
C11: 廃棄する機器の種類及び台数 | N11: 建物解体(含修繕・模様替え)の有無(下記該当に〇印)
C12: エアコンディショナー | G12: =IF(初期入力!$E$2="","",初期入力!$E$2) | H12: 冷蔵及び冷凍機器 | L12: =IF(初期入力!$E$3="","",初期入力!$E$3) | N12: 解体(修繕等)あり | S12: 解体(修繕等)なし
C13: フロン類の引渡し先 (右記該当枠にレ点) | H13: 第1種フロン類充填回収業者に直接依頼する (第1種フロン類充填回収業者欄に記入する) | P13: 取次者(1)に委託する (取次者(1)欄に記入する)
A15: 取次者(1) (第1種フロン類 引渡受託者) | C15: 取次者(1)の氏名又は名称 | G15: =IF(初期入力!$B$16="","",初期入力!$B$16) | O15: 回付の年月日 | R15: =IF(初期入力!$B$15="","",初期入力!$B$15)
C16: 上記の住所 | G16: =IF(初期入力!$B$17="","",初期入力!$B$17) | O16: 電 話 | R16: =IF(初期入力!$B$20="","",初期入力!$B$20)
C17: 担当者 | G17: 部署名 | H17: =IF(初期入力!$B$19="","",初期入力!$B$19) | K17: 氏名 | M17: =IF(初期入力!$B$18="","",初期入力!$B$18) | O17: F A X | R17: =IF(初期入力!$B$21="","",初期入力!$B$21)
A18: 整備の場合 : (第1種特定 製品の整備者) | C18: 下記の者にフロン類を引渡します。(引渡し先にレ点を記入)
C19: 取次者(2) | H19: 取次者(2)に再委託することを承諾します。 | O19: 承諾の年月日
C20: 第1種フロン類充填回収業者 | H20: 廃棄する機器所有者等 | L20: =IF(初期入力!$B$8="","",初期入力!$B$8) | O20: 担当者
H21: の氏名又は名称
A23: 取次者(2) (第1種フロン類 引渡受託者) | C23: 取次者(2)の氏名又は名称 | G23: =IF(初期入力!$B$25="","",初期入力!$B$25) | O23: 回付の年月日
C24: 上記の住所 | G24: =IF(初期入力!$B$26="","",初期入力!$B$26) | O24: 電 話 | R24: =IF(初期入力!$B$29="","",初期入力!$B$29)
C25: 担当者 | G25: 部署名 | H25: =IF(初期入力!$B$28="","",初期入力!$B$28) | K25: 氏名 | M25: =IF(初期入力!$B$27="","",初期入力!$B$27) | O25: F A X | R25: =IF(初期入力!$B$30="","",初期入力!$B$30)
C26: 下記の者にフロン類を引渡します。(引渡し先にレ点を記入)
C27: 取次者(3)→(別紙『補足用』を使用して下さい。) | L27: 第1種フロン類充填回収業者
A29: 第1種 フロン類 充填回収業者 | C29: 登録番号 | G29: =IF(初期入力!$B$33="","",初期入力!$B$33) -> 0110100851 | J29: フロン類引取り終了した年月日 | P29: 引取証明書 交付の年月日
C30: 登録都道府県 | G30: =IF(初期入力!$B$34="","",初期入力!$B$34) -> 北海道
C31: 第1種フロン類充填回収業者 | G31: =IF(初期入力!$B$35="","",初期入力!$B$35) -> テクノエンジニアリング㈱ | O31: 冷媒回収
C32: の氏名又は名称 | O32: 技術者氏名
C33: 上記の住所 | G33: =IF(初期入力!$B$36="","",初期入力!$B$36) -> 〒003-0011 札幌市白石区中央1条5丁目6-20 | O33: 電 話 | R33: =IF(初期入力!$B$42="","",初期入力!$B$42) -> 011-827-6330
C34: 担当者 | G34: 部署名 | K34: 氏名 | O34: F A X | R34: =IF(初期入力!$B$43="","",初期入力!$B$43) -> 011-827-6331
A36: 取次者 ( 1 ) の注意事項
A37: ①廃棄する機器所有者等 (以下、機器の所有者等) の承諾を得てフロン類の回収を再委託する場合は、C票の取次者(1)欄の回付の年月日
A38: を記入のうえ保存 (3年間) し、D票以下を再委託する取次者(2)へ回付します。
A39: ②フロン類の回収を第1種フロン類充填回収業者 (以下、充填回収業者) に依頼する場合は、充填回収業者欄に記入のうえ保存 (3年間) し、
A40: E票以下を充填回収業者に回付します (B票、D票は使用しません) 。
A41: ③機器の所有者等欄の交付の年月日から30日 (建物の全部または一部解体を伴う場合は90日) を経過してもE票 (写) が、機器の所有者等に
A42: 回付されない場合は、機器の所有者等から回収場所の都道府県知事に報告されますので、早めにフロン類の回収作業を依頼してください。
A44: (
A45: 引
A46: 渡
A47: し
...

Sheet D票
A1: D 票 | C1: 委託確認書 兼 再委託承諾書 (写) | S1: 取次者 ( 2 ) が保存
A3: 汎用版 (主に再委託用)
A5: 機器整備・修理 | D5: (機器の整備・修理時に使用する場合は、左記にレ点を記入) | O5: 伝票番号
A6: 廃棄する機器 の所有者等 | C6: 機器所有者等の氏名又は名称 | G6: =IF(初期入力!$B$4="","",初期入力!$B$4) | O6: 交付の年月日 | R6: =IF(初期入力!$B$2="","",初期入力!$B$2)
C7: 上記の住所 | G7: =IF(初期入力!$B$5="","",初期入力!$B$5) | O7: 電 話 | R7: =IF(初期入力!$B$11="","",初期入力!$B$11)
A8: (第1種特定製品 廃棄等実施者) | C8: 担当者 | G8: 部署名 | H8: =IF(初期入力!$B$10="","",初期入力!$B$10) | K8: 氏名 | M8: =IF(初期入力!$B$9="","",初期入力!$B$9) | O8: F A X | R8: =IF(初期入力!$B$12="","",初期入力!$B$12)
C9: 廃棄する機器がある施設(建物)名 | G9: =IF(初期入力!$B$6="","",初期入力!$B$6)
A10: 整備の場合 : 整備する機器の 所有者等 (第1種特定製品 の整備の発注者) | C10: 上記の住所 | G10: =IF(初期入力!$B$7="","",初期入力!$B$7)
C11: 廃棄する機器の種類及び台数 | N11: 建物解体(含修繕・模様替え)の有無(下記該当に〇印)
C12: エアコンディショナー | G12: =IF(初期入力!$E$2="","",初期入力!$E$2) | H12: 冷蔵及び冷凍機器 | L12: =IF(初期入力!$E$3="","",初期入力!$E$3) | N12: 解体(修繕等)あり | S12: 解体(修繕等)なし
C13: フロン類の引渡し先 (右記該当枠にレ点) | H13: 第1種フロン類充填回収業者に直接依頼する (第1種フロン類充填回収業者欄に記入する) | P13: 取次者(1)に委託する (取次者(1)欄に記入する)
A15: 取次者(1) (第1種フロン類 引渡受託者) | C15: 取次者(1)の氏名又は名称 | G15: =IF(初期入力!$B$16="","",初期入力!$B$16) | O15: 回付の年月日 | R15: =IF(初期入力!$B$15="","",初期入力!$B$15)
C16: 上記の住所 | G16: =IF(初期入力!$B$17="","",初期入力!$B$17) | O16: 電 話 | R16: =IF(初期入力!$B$20="","",初期入力!$B$20)
C17: 担当者 | G17: 部署名 | H17: =IF(初期入力!$B$19="","",初期入力!$B$19) | K17: 氏名 | M17: =IF(初期入力!$B$18="","",初期入力!$B$18) | O17: F A X | R17: =IF(初期入力!$B$21="","",初期入力!$B$21)
A18: 整備の場合 : (第1種特定 製品の整備者) | C18: 下記の者にフロン類を引渡します。(引渡し先にレ点を記入)
C19: 取次者(2) | H19: 取次者(2)に再委託することを承諾します。 | O19: 承諾の年月日
C20: 第1種フロン類充填回収業者 | H20: 廃棄する機器所有者等 | L20: =IF(初期入力!$B$8="","",初期入力!$B$8) | O20: 担当者
H21: の氏名又は名称
A23: 取次者(2) (第1種フロン類 引渡受託者) | C23: 取次者(2)の氏名又は名称 | G23: =IF(初期入力!$B$25="","",初期入力!$B$25) | O23: 回付の年月日 | R23: =IF(初期入力!$B$24="","",初期入力!$B$24)
C24: 上記の住所 | G24: =IF(初期入力!$B$26="","",初期入力!$B$26) | O24: 電 話 | R24: =IF(初期入力!$B$29="","",初期入力!$B$29)
C25: 担当者 | G25: 部署名 | H25: =IF(初期入力!$B$28="","",初期入力!$B$28) | K25: 氏名 | M25: =IF(初期入力!$B$27="","",初期入力!$B$27) | O25: F A X | R25: =IF(初期入力!$B$30="","",初期入力!$B$30)
C26: 下記の者にフロン類を引渡します。(引渡し先にレ点を記入)
C27: 取次者(3)→(別紙『補足用』を使用して下さい。) | L27: 第1種フロン類充填回収業者
A29: 第1種 フロン類 充填回収業者 | C29: 登録番号 | G29: =IF(初期入力!$B$33="","",初期入力!$B$33) -> 0110100851 | J29: フロン類引取り終了した年月日 | P29: 引取証明書 交付の年月日
C30: 登録都道府県 | G30: =IF(初期入力!$B$34="","",初期入力!$B$34) -> 北海道
C31: 第1種フロン類充填回収業者 | G31: =IF(初期入力!$B$35="","",初期入力!$B$35) -> テクノエンジニアリング㈱ | O31: 冷媒回収
C32: の氏名又は名称 | O32: 技術者氏名
C33: 上記の住所 | G33: =IF(初期入力!$B$36="","",初期入力!$B$36) -> 〒003-0011 札幌市白石区中央1条5丁目6-20 | O33: 電 話 | R33: =IF(初期入力!$B$42="","",初期入力!$B$42) -> 011-827-6330
C34: 担当者 | G34: 部署名 | K34: 氏名 | O34: F A X | R34: =IF(初期入力!$B$43="","",初期入力!$B$43) -> 011-827-6331
A36: 取次者 ( 2 ) の注意事項
A37: ①フロン類の回収を第1種フロン類充填回収業 (以上、充填回収業者) に依頼するか、取次者(3)に再々委託しなければなりません。
A38: ②充填回収業者に依頼する場合は、取次者(2)欄および充填回収業者に記入のうえ、D票を保存 (3年間) し、E票以下を充填回収業者に
A39: 回付してください。
A40: ③取次者(3)にフロン類の回収をさらに委託する場合は、取次者(3)に別紙の「補足用」とともにE票以下を回付してください。
A41: ④廃棄する機器所有者等 (以下、機器の所有者等) 欄の交付の年月日から30日 (建物の全部または一部解体を伴う場合は、90日) を経過しても
A42: E票(写)が、機器の所有者等に回付されない場合は、機器の所有者等から回収場所の都道府県知事に報告されますので、早めにフロン類の
A43: 回収作業を依頼してください。
A45: (
A46: 引
A47: 渡
...

Sheet E票
A1: E 票 | C1: 委託確認書 兼 引取証明書 | O1: 機器の所有者等および最終取次者が保存
A3: 汎用版 (主に再委託用)
A5: 機器整備・修理 | D5: (機器の整備・修理時に使用する場合は、左記にレ点を記入) | O5: 伝票番号
A6: 廃棄する機器 の所有者等 | C6: 機器所有者等の氏名又は名称 | G6: =IF(初期入力!$B$4="","",初期入力!$B$4) | O6: 交付の年月日 | S6: =IF(初期入力!$B$2="","",初期入力!$B$2)
C7: 上記の住所 | G7: =IF(初期入力!$B$5="","",初期入力!$B$5) | O7: 電 話 | S7: =IF(初期入力!$B$11="","",初期入力!$B$11)
A8: (第1種特定製品 廃棄等実施者) | C8: 担当者 | G8: 部署名 | H8: =IF(初期入力!$B$10="","",初期入力!$B$10) | K8: 氏名 | M8: =IF(初期入力!$B$9="","",初期入力!$B$9) | O8: F A X | S8: =IF(初期入力!$B$12="","",初期入力!$B$12)
C9: 廃棄する機器がある施設(建物)名 | G9: =IF(初期入力!$B$6="","",初期入力!$B$6)
A10: 整備の場合 : 整備する機器の 所有者等 (第1種特定製品 の整備の発注者) | C10: 上記の住所 | G10: =IF(初期入力!$B$7="","",初期入力!$B$7)
C11: 廃棄する機器の種類及び台数 | N11: 建物解体(含修繕・模様替え)の有無(下記該当に〇印)
C12: エアコンディショナー | G12: =IF(初期入力!$E$2="","",初期入力!$E$2) | H12: 冷蔵及び冷凍機器 | L12: =IF(初期入力!$E$3="","",初期入力!$E$3) | N12: 解体(修繕等)あり | T12: 解体(修繕等)なし
C13: フロン類の引渡し先 (右記該当枠にレ点) | H13: 第1種フロン類充填回収業者に直接依頼する (第1種フロン類充填回収業者欄に記入する) | Q13: 取次者(1)に委託する (取次者(1)欄に記入する)
A15: 取次者(1) (第1種フロン類 引渡受託者) | C15: 取次者(1)の氏名又は名称 | G15: =IF(初期入力!$B$16="","",初期入力!$B$16) | O15: 回付の年月日 | S15: =IF(初期入力!$B$15="","",初期入力!$B$15)
C16: 上記の住所 | G16: =IF(初期入力!$B$17="","",初期入力!$B$17) | O16: 電 話 | S16: =IF(初期入力!$B$20="","",初期入力!$B$20)
C17: 担当者 | G17: 部署名 | H17: =IF(初期入力!$B$19="","",初期入力!$B$19) | K17: 氏名 | M17: =IF(初期入力!$B$18="","",初期入力!$B$18) | O17: F A X | S17: =IF(初期入力!$B$21="","",初期入力!$B$21)
A18: 整備の場合 : (第1種特定 製品の整備者) | C18: 下記の者にフロン類を引渡します。(引渡し先にレ点を記入)
C19: 取次者(2) | H19: 取次者(2)に再委託することを承諾します。 | O19: 承諾の年月日
C20: 第1種フロン類充填回収業者 | H20: 廃棄する機器所有者等 | L20: =IF(初期入力!$B$8="","",初期入力!$B$8) | O20: 担当者
H21: の氏名又は名称
A23: 取次者(2) (第1種フロン類 引渡受託者) | C23: 取次者(2)の氏名又は名称 | G23: =IF(初期入力!$B$25="","",初期入力!$B$25) | O23: 回付の年月日 | S23: =IF(初期入力!$B$24="","",初期入力!$B$24)
C24: 上記の住所 | G24: =IF(初期入力!$B$26="","",初期入力!$B$26) | O24: 電 話 | S24: =IF(初期入力!$B$29="","",初期入力!$B$29)
C25: 担当者 | G25: 部署名 | H25: =IF(初期入力!$B$28="","",初期入力!$B$28) | K25: 氏名 | M25: =IF(初期入力!$B$27="","",初期入力!$B$27) | O25: F A X | S25: =IF(初期入力!$B$30="","",初期入力!$B$30)
C26: 下記の者にフロン類を引渡します。(引渡し先にレ点を記入)
C27: 取次者(3)→(別紙『補足用』を使用して下さい。) | L27: 第1種フロン類充填回収業者
A29: 第1種 フロン類 充填回収業者 | C29: 登録番号 | G29: =IF(初期入力!$B$33="","",初期入力!$B$33) -> 0110100851 | J29: フロン類引取り終了した年月日 | N29: =IF(初期入力!$B$40="","",初期入力!$B$40) | Q29: 引取証明書 交付の年月日 | W29: =IF(初期入力!$B$41="","",初期入力!$B$41)
C30: 登録都道府県 | G30: =IF(初期入力!$B$34="","",初期入力!$B$34) -> 北海道
C31: 第1種フロン類充填回収業者 | G31: =IF(初期入力!$B$35="","",初期入力!$B$35) -> テクノエンジニアリング㈱ | O31: 冷媒回収 | S31: =IF(初期入力!$B$39="","",初期入力!$B$39) -> 中野 勝之
C32: の氏名又は名称 | O32: 技術者氏名
C33: 上記の住所 | G33: =IF(初期入力!$B$36="","",初期入力!$B$36) -> 〒003-0011 札幌市白石区中央1条5丁目6-20 | O33: 電 話 | S33: =IF(初期入力!$B$42="","",初期入力!$B$42) -> 011-827-6330
C34: 担当者 | G34: 部署名 | H34: =IF(初期入力!$B$38="","",初期入力!$B$38) -> 工事部 | K34: 氏名 | M34: =IF(初期入力!$B$37="","",初期入力!$B$37) -> 中野 勝之 | O34: F A X | S34: =IF(初期入力!$B$43="","",初期入力!$B$43) -> 011-827-6331
A36: 下記の通りフロンを回収しました。 | O36: 管理番号 | R36: 2 | T36: 0 | U36: 2 | V36: 1 | W36: 1 | X36: 1 | Y36: 1 | Z36: 5 | AA36: 0 | AB36: 0
A37: 回収量等 | B37: フロンの種類 | E37: CFC | H37: HCFC | N37: HFC | T37: 計
B38: 第1種
B39: 特定製品の種類
B40: エアコンディショナー | E40: =IF(初期入力!$E$16="","",初期入力!$E$16) | F40: =IF(初期入力!$F$16="","",初期入力!$F$16) | H40: =IF(初期入力!$G$16="","",初期入力!$G$16) | K40: =IF(初期入力!$H$16="","",初期入力!$H$16) | N40: =IF(初期入力!$I$16="","",初期入力!$I$16) | P40: =IF(初期入力!$J$16="","",初期入力!$J$16) | T40: =IF(初期入力!$K$16="","",初期入力!$K$16) | X40: =IF(初期入力!$L$16="","",初期入力!$L$16)
B41: 冷蔵機器及び冷凍機器 | E41: =IF(初期入力!$E$17="","",初期入力!$E$17) | F41: =IF(初期入力!$F$17="","",初期入力!$F$17) | H41: =IF(初期入力!$G$17="","",初期入力!$G$17) | K41: =IF(初期入力!$H$17="","",初期入力!$H$17) | N41: =IF(初期入力!$I$17="","",初期入力!$I$17) | P41: =IF(初期入力!$J$17="","",初期入力!$J$17) | T41: =IF(初期入力!$K$17="","",初期入力!$K$17) | X41: =IF(初期入力!$L$17="","",初期入力!$L$17)
B42: 計 | E42: =IF(初期入力!$E$18="","",初期入力!$E$18) | F42: =IF(初期入力!$F$18="","",初期入力!$F$18) | H42: =IF(初期入力!$G$18="","",初期入力!$G$18) | K42: =IF(初期入力!$H$18="","",初期入力!$H$18) | N42: =IF(初期入力!$I$18="","",初期入力!$I$18) | P42: =IF(初期入力!$J$18="","",初期入力!$J$18) | T42: =IF(初期入力!$K$18="","",初期入力!$K$18) | X42: =IF(初期入力!$L$18="","",初期入力!$L$18)
A43: 銘板に記載されている充填量 | E43: =IF(初期入力!$E$19="","",初期入力!$E$19) | F43: =IF(初期入力!$F$19="","",初期入力!$F$19) | H43: =IF(初期入力!$G$19="","",初期入力!$G$19) | K43: =IF(初期入力!$H$19="","",初期入力!$H$19) | N43: =IF(初期入力!$I$19="","",初期入力!$I$19) | P43: =IF(初期入力!$J$19="","",初期入力!$J$19) | T43: =IF(初期入力!$K$19="","",初期入力!$K$19) | X43: =IF(初期入力!$L$19="","",初期入力!$L$19)
A44: (判る範囲で記入する)
A45: フロン類が回収できなかった場合の台数及び要因 | F45: =IF(初期入力!$E$20="","",初期入力!$E$20) -> 0 | H45: 要因 :
A47: 第1種フロン類充填回収業者 ( 以下、充填回収業者 ) の注意事項
...

Sheet F票
A1: F 票 | C1: 引取証明書 ( 写 ) | T1: 充填回収業者が保存
A3: 汎用版 (主に再委託用)
A5: 機器整備・修理 | D5: (機器の整備・修理時に使用する場合は、左記にレ点を記入) | O5: 伝票番号
A6: 廃棄する機器 の所有者等 | C6: 機器所有者等の氏名又は名称 | G6: =IF(初期入力!$B$4="","",初期入力!$B$4) | O6: 交付の年月日 | S6: =IF(初期入力!$B$2="","",初期入力!$B$2)
C7: 上記の住所 | G7: =IF(初期入力!$B$5="","",初期入力!$B$5) | O7: 電 話 | S7: =IF(初期入力!$B$11="","",初期入力!$B$11)
A8: (第1種特定製品 廃棄等実施者) | C8: 担当者 | G8: 部署名 | H8: =IF(初期入力!$B$10="","",初期入力!$B$10) | K8: 氏名 | M8: =IF(初期入力!$B$9="","",初期入力!$B$9) | O8: F A X | S8: =IF(初期入力!$B$12="","",初期入力!$B$12)
C9: 廃棄する機器がある施設(建物)名 | G9: =IF(初期入力!$B$6="","",初期入力!$B$6)
A10: 整備の場合 : 整備する機器の 所有者等 (第1種特定製品 の整備の発注者) | C10: 上記の住所 | G10: =IF(初期入力!$B$7="","",初期入力!$B$7)
C11: 廃棄する機器の種類及び台数 | N11: 建物解体(含修繕・模様替え)の有無(下記該当に〇印)
C12: エアコンディショナー | G12: =IF(初期入力!$E$2="","",初期入力!$E$2) | H12: 冷蔵及び冷凍機器 | L12: =IF(初期入力!$E$3="","",初期入力!$E$3) | N12: 解体(修繕等)あり | T12: 解体(修繕等)なし
C13: フロン類の引渡し先 (右記該当枠にレ点) | H13: 第1種フロン類充填回収業者に直接依頼する (第1種フロン類充填回収業者欄に記入する) | Q13: 取次者(1)に委託する (取次者(1)欄に記入する)
A15: 取次者(1) (第1種フロン類 引渡受託者) | C15: 取次者(1)の氏名又は名称 | G15: =IF(初期入力!$B$16="","",初期入力!$B$16) | O15: 回付の年月日 | S15: =IF(初期入力!$B$15="","",初期入力!$B$15)
C16: 上記の住所 | G16: =IF(初期入力!$B$17="","",初期入力!$B$17) | O16: 電 話 | S16: =IF(初期入力!$B$20="","",初期入力!$B$20)
C17: 担当者 | G17: 部署名 | H17: =IF(初期入力!$B$19="","",初期入力!$B$19) | K17: 氏名 | M17: =IF(初期入力!$B$18="","",初期入力!$B$18) | O17: F A X | S17: =IF(初期入力!$B$21="","",初期入力!$B$21)
A18: 整備の場合 : (第1種特定 製品の整備者) | C18: 下記の者にフロン類を引渡します。(引渡し先にレ点を記入)
C19: 取次者(2) | H19: 取次者(2)に再委託することを承諾します。 | O19: 承諾の年月日 | S19: =IF(初期入力!$B$3="","",初期入力!$B$3)
C20: 第1種フロン類充填回収業者 | H20: 廃棄する機器所有者等 | L20: =IF(初期入力!$B$8="","",初期入力!$B$8) | O20: 担当者 | S20: =IF(初期入力!$B$9="","",初期入力!$B$9)
H21: の氏名又は名称
A23: 取次者(2) (第1種フロン類 引渡受託者) | C23: 取次者(2)の氏名又は名称 | G23: =IF(初期入力!$B$25="","",初期入力!$B$25) | O23: 回付の年月日 | S23: =IF(初期入力!$B$24="","",初期入力!$B$24)
C24: 上記の住所 | G24: =IF(初期入力!$B$26="","",初期入力!$B$26) | O24: 電 話 | S24: =IF(初期入力!$B$29="","",初期入力!$B$29)
C25: 担当者 | G25: 部署名 | H25: =IF(初期入力!$B$28="","",初期入力!$B$28) | K25: 氏名 | M25: =IF(初期入力!$B$27="","",初期入力!$B$27) | O25: F A X | S25: =IF(初期入力!$B$30="","",初期入力!$B$30)
C26: 下記の者にフロン類を引渡します。(引渡し先にレ点を記入)
C27: 取次者(3)→(別紙『補足用』を使用して下さい。) | L27: 第1種フロン類充填回収業者
A29: 第1種 フロン類 充填回収業者 | C29: 登録番号 | G29: =IF(初期入力!$B$33="","",初期入力!$B$33) -> 0110100851 | J29: フロン類引取り終了した年月日 | N29: =IF(初期入力!$B$40="","",初期入力!$B$40) | Q29: 引取証明書 交付の年月日 | W29: =IF(初期入力!$B$41="","",初期入力!$B$41)
C30: 登録都道府県 | G30: =IF(初期入力!$B$34="","",初期入力!$B$34) -> 北海道
C31: 第1種フロン類充填回収業者 | G31: =IF(初期入力!$B$35="","",初期入力!$B$35) -> テクノエンジニアリング㈱ | O31: 冷媒回収 | S31: =IF(初期入力!$B$39="","",初期入力!$B$39) -> 中野 勝之
C32: の氏名又は名称 | O32: 技術者氏名
C33: 上記の住所 | G33: =IF(初期入力!$B$36="","",初期入力!$B$36) -> 〒003-0011 札幌市白石区中央1条5丁目6-20 | O33: 電 話 | S33: =IF(初期入力!$B$42="","",初期入力!$B$42) -> 011-827-6330
C34: 担当者 | G34: 部署名 | H34: =IF(初期入力!$B$38="","",初期入力!$B$38) -> 工事部 | K34: 氏名 | M34: =IF(初期入力!$B$37="","",初期入力!$B$37) -> 中野 勝之 | O34: F A X | S34: =IF(初期入力!$B$43="","",初期入力!$B$43) -> 011-827-6331
A36: 下記の通りフロンを回収しました。 | O36: 管理番号 | R36: 2 | T36: 0 | U36: 2 | V36: 1 | W36: 1 | X36: 1 | Y36: 1 | Z36: 5 | AA36: 0 | AB36: 0
A37: 回収量等 | B37: フロンの種類 | E37: CFC | H37: HCFC | N37: HFC | T37: 計
B38: 第1種
B39: 特定製品の種類
B40: エアコンディショナー | E40: =IF(初期入力!$E$16="","",初期入力!$E$16) | F40: =IF(初期入力!$F$16="","",初期入力!$F$16) | H40: =IF(初期入力!$G$16="","",初期入力!$G$16) | K40: =IF(初期入力!$H$16="","",初期入力!$H$16) | N40: =IF(初期入力!$I$16="","",初期入力!$I$16) | P40: =IF(初期入力!$J$16="","",初期入力!$J$16) | T40: =IF(初期入力!$K$16="","",初期入力!$K$16) | X40: =IF(初期入力!$L$16="","",初期入力!$L$16)
B41: 冷蔵機器及び冷凍機器 | E41: =IF(初期入力!$E$17="","",初期入力!$E$17) | F41: =IF(初期入力!$F$17="","",初期入力!$F$17) | H41: =IF(初期入力!$G$17="","",初期入力!$G$17) | K41: =IF(初期入力!$H$17="","",初期入力!$H$17) | N41: =IF(初期入力!$I$17="","",初期入力!$I$17) | P41: =IF(初期入力!$J$17="","",初期入力!$J$17) | T41: =IF(初期入力!$K$17="","",初期入力!$K$17) | X41: =IF(初期入力!$L$17="","",初期入力!$L$17)
B42: 計 | E42: =IF(初期入力!$E$18="","",初期入力!$E$18) | F42: =IF(初期入力!$F$18="","",初期入力!$F$18) | H42: =IF(初期入力!$G$18="","",初期入力!$G$18) | K42: =IF(初期入力!$H$18="","",初期入力!$H$18) | N42: =IF(初期入力!$I$18="","",初期入力!$I$18) | P42: =IF(初期入力!$J$18="","",初期入力!$J$18) | T42: =IF(初期入力!$K$18="","",初期入力!$K$18) | X42: =IF(初期入力!$L$18="","",初期入力!$L$18)
A43: 銘板に記載されている充填量 | E43: =IF(初期入力!$E$19="","",初期入力!$E$19) | F43: =IF(初期入力!$F$19="","",初期入力!$F$19) | H43: =IF(初期入力!$G$19="","",初期入力!$G$19) | K43: =IF(初期入力!$H$19="","",初期入力!$H$19) | N43: =IF(初期入力!$I$19="","",初期入力!$I$19) | P43: =IF(初期入力!$J$19="","",初期入力!$J$19) | T43: =IF(初期入力!$K$19="","",初期入力!$K$19) | X43: =IF(初期入力!$L$19="","",初期入力!$L$19)
A44: (判る範囲で記入する)
A45: フロン類が回収できなかった場合の台数及び要因 | F45: =IF(初期入力!$E$20="","",初期入力!$E$20) -> 0 | H45: 要因 :
A47: 回収したフロン類の処理方法等
...
